<?xml version="1.0" encoding="UTF-8"?>
<testng-results total="6" passed="3" failed="1" skipped="2">
  <reporter-output>
  </reporter-output>
  <suite started-at="2024-09-21T20:31:53Z" name="Myntra" finished-at="2024-09-21T20:32:07Z" duration-ms="14178">
    <groups>
    </groups>
    <test started-at="2024-09-21T20:31:53Z" name="Test" finished-at="2024-09-21T20:32:07Z" duration-ms="14178">
      <class name="com.Myntra.Women">
        <test-method is-config="true" signature="applicationLaunch()[pri:0, instance:com.Myntra.Women@ca30bc1]" started-at="2024-09-22T02:01:53Z" name="applicationLaunch" finished-at="2024-09-22T02:02:00Z" duration-ms="7327" status="PASS">
          <reporter-output>
          </reporter-output>
        </test-method> <!-- applicationLaunch -->
        <test-method signature="women()[pri:2, instance:com.Myntra.Women@ca30bc1]" started-at="2024-09-22T02:02:00Z" name="women" finished-at="2024-09-22T02:02:02Z" duration-ms="1247" status="SKIP">
          <exception class="java.lang.AssertionError">
            <message>
              <![CDATA[The following asserts failed:
	Assertion failure expected [men] but found [WOMEN]]]>
            </message>
            <full-stacktrace>
              <![CDATA[java.lang.AssertionError: The following asserts failed:
	Assertion failure expected [men] but found [WOMEN]
	at org.testng.asserts.SoftAssert.assertAll(SoftAssert.java:43)
	at com.Myntra.Women.women(Women.java:50)
	at java.base/jdk.internal.reflect.NativeMethodAccessorImpl.invoke0(Native Method)
	at java.base/jdk.internal.reflect.NativeMethodAccessorImpl.invoke(NativeMethodAccessorImpl.java:77)
	at java.base/jdk.internal.reflect.DelegatingMethodAccessorImpl.invoke(DelegatingMethodAccessorImpl.java:43)
	at java.base/java.lang.reflect.Method.invoke(Method.java:568)
	at org.testng.internal.MethodInvocationHelper.invokeMethod(MethodInvocationHelper.java:86)
	at org.testng.internal.Invoker.invokeMethod(Invoker.java:643)
	at org.testng.internal.Invoker.invokeTestMethod(Invoker.java:820)
	at org.testng.internal.Invoker.invokeTestMethods(Invoker.java:1128)
	at org.testng.internal.TestMethodWorker.invokeTestMethods(TestMethodWorker.java:129)
	at org.testng.internal.TestMethodWorker.run(TestMethodWorker.java:112)
	at org.testng.TestRunner.privateRun(TestRunner.java:782)
	at org.testng.TestRunner.run(TestRunner.java:632)
	at org.testng.SuiteRunner.runTest(SuiteRunner.java:366)
	at org.testng.SuiteRunner.runSequentially(SuiteRunner.java:361)
	at org.testng.SuiteRunner.privateRun(SuiteRunner.java:319)
	at org.testng.SuiteRunner.run(SuiteRunner.java:268)
	at org.testng.SuiteRunnerWorker.runSuite(SuiteRunnerWorker.java:52)
	at org.testng.SuiteRunnerWorker.run(SuiteRunnerWorker.java:86)
	at org.testng.TestNG.runSuitesSequentially(TestNG.java:1244)
	at org.testng.TestNG.runSuitesLocally(TestNG.java:1169)
	at org.testng.TestNG.run(TestNG.java:1064)
	at org.testng.remote.AbstractRemoteTestNG.run(AbstractRemoteTestNG.java:115)
	at org.testng.remote.RemoteTestNG.initAndRun(RemoteTestNG.java:293)
	at org.testng.remote.RemoteTestNG.main(RemoteTestNG.java:91)
]]>
            </full-stacktrace>
          </exception> <!-- java.lang.AssertionError -->
          <reporter-output>
          </reporter-output>
        </test-method> <!-- women -->
        <test-method signature="women()[pri:2, instance:com.Myntra.Women@ca30bc1]" started-at="2024-09-22T02:02:02Z" name="women" finished-at="2024-09-22T02:02:02Z" duration-ms="726" status="SKIP">
          <exception class="java.lang.AssertionError">
            <message>
              <![CDATA[The following asserts failed:
	Assertion failure expected [men] but found [WOMEN]]]>
            </message>
            <full-stacktrace>
              <![CDATA[java.lang.AssertionError: The following asserts failed:
	Assertion failure expected [men] but found [WOMEN]
	at org.testng.asserts.SoftAssert.assertAll(SoftAssert.java:43)
	at com.Myntra.Women.women(Women.java:50)
	at java.base/jdk.internal.reflect.NativeMethodAccessorImpl.invoke0(Native Method)
	at java.base/jdk.internal.reflect.NativeMethodAccessorImpl.invoke(NativeMethodAccessorImpl.java:77)
	at java.base/jdk.internal.reflect.DelegatingMethodAccessorImpl.invoke(DelegatingMethodAccessorImpl.java:43)
	at java.base/java.lang.reflect.Method.invoke(Method.java:568)
	at org.testng.internal.MethodInvocationHelper.invokeMethod(MethodInvocationHelper.java:86)
	at org.testng.internal.Invoker.invokeMethod(Invoker.java:643)
	at org.testng.internal.Invoker.retryFailed(Invoker.java:967)
	at org.testng.internal.Invoker.invokeTestMethods(Invoker.java:1146)
	at org.testng.internal.TestMethodWorker.invokeTestMethods(TestMethodWorker.java:129)
	at org.testng.internal.TestMethodWorker.run(TestMethodWorker.java:112)
	at org.testng.TestRunner.privateRun(TestRunner.java:782)
	at org.testng.TestRunner.run(TestRunner.java:632)
	at org.testng.SuiteRunner.runTest(SuiteRunner.java:366)
	at org.testng.SuiteRunner.runSequentially(SuiteRunner.java:361)
	at org.testng.SuiteRunner.privateRun(SuiteRunner.java:319)
	at org.testng.SuiteRunner.run(SuiteRunner.java:268)
	at org.testng.SuiteRunnerWorker.runSuite(SuiteRunnerWorker.java:52)
	at org.testng.SuiteRunnerWorker.run(SuiteRunnerWorker.java:86)
	at org.testng.TestNG.runSuitesSequentially(TestNG.java:1244)
	at org.testng.TestNG.runSuitesLocally(TestNG.java:1169)
	at org.testng.TestNG.run(TestNG.java:1064)
	at org.testng.remote.AbstractRemoteTestNG.run(AbstractRemoteTestNG.java:115)
	at org.testng.remote.RemoteTestNG.initAndRun(RemoteTestNG.java:293)
	at org.testng.remote.RemoteTestNG.main(RemoteTestNG.java:91)
]]>
            </full-stacktrace>
          </exception> <!-- java.lang.AssertionError -->
          <reporter-output>
          </reporter-output>
        </test-method> <!-- women -->
        <test-method signature="women()[pri:2, instance:com.Myntra.Women@ca30bc1]" started-at="2024-09-22T02:02:02Z" name="women" finished-at="2024-09-22T02:02:04Z" duration-ms="2050" status="FAIL">
          <exception class="java.lang.AssertionError">
            <message>
              <![CDATA[The following asserts failed:
	Assertion failure expected [men] but found [WOMEN]]]>
            </message>
            <full-stacktrace>
              <![CDATA[java.lang.AssertionError: The following asserts failed:
	Assertion failure expected [men] but found [WOMEN]
	at org.testng.asserts.SoftAssert.assertAll(SoftAssert.java:43)
	at com.Myntra.Women.women(Women.java:50)
	at java.base/jdk.internal.reflect.NativeMethodAccessorImpl.invoke0(Native Method)
	at java.base/jdk.internal.reflect.NativeMethodAccessorImpl.invoke(NativeMethodAccessorImpl.java:77)
	at java.base/jdk.internal.reflect.DelegatingMethodAccessorImpl.invoke(DelegatingMethodAccessorImpl.java:43)
	at java.base/java.lang.reflect.Method.invoke(Method.java:568)
	at org.testng.internal.MethodInvocationHelper.invokeMethod(MethodInvocationHelper.java:86)
	at org.testng.internal.Invoker.invokeMethod(Invoker.java:643)
	at org.testng.internal.Invoker.retryFailed(Invoker.java:967)
	at org.testng.internal.Invoker.invokeTestMethods(Invoker.java:1146)
	at org.testng.internal.TestMethodWorker.invokeTestMethods(TestMethodWorker.java:129)
	at org.testng.internal.TestMethodWorker.run(TestMethodWorker.java:112)
	at org.testng.TestRunner.privateRun(TestRunner.java:782)
	at org.testng.TestRunner.run(TestRunner.java:632)
	at org.testng.SuiteRunner.runTest(SuiteRunner.java:366)
	at org.testng.SuiteRunner.runSequentially(SuiteRunner.java:361)
	at org.testng.SuiteRunner.privateRun(SuiteRunner.java:319)
	at org.testng.SuiteRunner.run(SuiteRunner.java:268)
	at org.testng.SuiteRunnerWorker.runSuite(SuiteRunnerWorker.java:52)
	at org.testng.SuiteRunnerWorker.run(SuiteRunnerWorker.java:86)
	at org.testng.TestNG.runSuitesSequentially(TestNG.java:1244)
	at org.testng.TestNG.runSuitesLocally(TestNG.java:1169)
	at org.testng.TestNG.run(TestNG.java:1064)
	at org.testng.remote.AbstractRemoteTestNG.run(AbstractRemoteTestNG.java:115)
	at org.testng.remote.RemoteTestNG.initAndRun(RemoteTestNG.java:293)
	at org.testng.remote.RemoteTestNG.main(RemoteTestNG.java:91)
]]>
            </full-stacktrace>
          </exception> <!-- java.lang.AssertionError -->
          <reporter-output>
          </reporter-output>
        </test-method> <!-- women -->
        <test-method signature="validateWomanPage()[pri:3, instance:com.Myntra.Women@ca30bc1]" started-at="2024-09-22T02:02:04Z" name="validateWomanPage" finished-at="2024-09-22T02:02:05Z" duration-ms="327" status="PASS">
          <reporter-output>
          </reporter-output>
        </test-method> <!-- validateWomanPage -->
        <test-method signature="clickOnBiba()[pri:4, instance:com.Myntra.Women@ca30bc1]" started-at="2024-09-22T02:02:05Z" name="clickOnBiba" finished-at="2024-09-22T02:02:07Z" duration-ms="1903" status="PASS">
          <reporter-output>
          </reporter-output>
        </test-method> <!-- clickOnBiba -->
        <test-method signature="validateBiba()[pri:5, instance:com.Myntra.Women@ca30bc1]" started-at="2024-09-22T02:02:07Z" name="validateBiba" finished-at="2024-09-22T02:02:07Z" duration-ms="570" status="PASS">
          <reporter-output>
          </reporter-output>
        </test-method> <!-- validateBiba -->
      </class> <!-- com.Myntra.Women -->
    </test> <!-- Test -->
  </suite> <!-- Myntra -->
</testng-results>
